Workbook
Name DiasCategorias: #REF!
Name DiasCategorias: #REF!
Name FechaInicio: #REF!
Name FechaInicio: #REF!
Name x_customMessage: Procesos!$AG$1129

Sheet Procesos
C1: SEGUIMIENTO A TÉRMINOS PROCESALES - PROCESOS | J1: =IF(G1085="","",(IF(N1085="","Pendiente primera actuación",IF(N1085="N.A.","N.A.",IF(NETWORKDAYS((G1085+1),N1085,'Días No Laborales'!$A$2:$U$145)<=20,"SI","NO"))))) -> SI
B4: Juzgado: | C4: JUZGADO 004 CIVIL MUNICIPAL DE ENVIDAGO
A6: N° | B6: Radicado | C6: Clase de proceso | D6: Sub clase de proceso | E6: Cuantía | F6: Concepto de Ingreso | G6: Fecha de ingreso | H6: Demandante(s) | I6: M | J6: F | K6: Demandado(s) | L6: M | M6: F | N6: FECHA DEL AUTO PRIMERA ACTUACIÓN dd-mm-aaaa | O6: ¿CUMPLIÓ PRIMERA ACTUACIÓN DENTRO DEL TÉRMINO? (SI/NO) | P6: OBSERVACIONES (EN CASO DE NO CUMPLIR LOS TÉRMINOS) | Q6: PERSPECTIVA DE GÉNERO (SI/NO) | R6: Fecha de notificación al último de los ddos | S6: ALERTA | T6: Pérdida de competencia en 1a. Instancia | U6: Pérdida de competencia en 2a instancia | V6: No. DE DÍAS | W6: FECHA DE SENTENCIA O DECISIÓN DEFINITIVA PRIMERA INSTANCIA (dd-mm-aaaa) | X6: FINALIZADO / DESCARGA EN ESTADÍSTICA | Y6: FECHA DE SENTENCIA O DECISIÓN DEFINITIVA SEGUNDA INSTANCIA (dd-mm-aaaa) | Z6: No. DE DÍAS FIN DEL PROCESO PRIMERA INSTANCIA | AA6: No. DE DÍAS FIN DEL PROCESO SEGUNDA INSTANCIA | AB6: CAUSAL DE TERMINACIÓN DEFINITIVA (ACORDE CON LA ESTADÍSTICA) | AC6: TRIMESTRE DE SALIDA | AD6: ULTIMA ACTUACIÓN | AE6: FECHA ÚLTIMA ACTUACIÓN | AF6: TRAMITADOR | AG6: ORIGEN | AH6: UBICACIÓN | AI6: FECHA ARCHIVO DEFINITIVO | AJ6: INICIO TP | AK6: FIN TP | AL6: FECHA TERMINACIÓN TRÁMITE POSTERIOR | AM6: OBSERVACIONES
C7: RESTITUCION BIEN INMUEBLE | D7: VERBAL SUMARIO | E7: MINIMA | F7: REMITIDA POR OTRO DESPACHO | G7: 45565 | H7: VISTA INMOBILIARIA SAS | I7: 1 | J7: 0 | K7: SEBASTIAN COLORADO SALZAR | L7: 1 | M7: 0 | N7: 45565 | O7: =IF(G7="","",(IF(N7="","Pendiente primera actuación",IF(N7="N.A.","N.A.",IF(NETWORKDAYS((G7+1),N7,'Días No Laborales'!$A$2:$U$145)<=20,"SI","NO"))))) -> SI | Q7: NO | Y7: N/A | Z7: =IF(B7="","",IF(W7="","Pendiente de sentencia",IF(W7="N.A.","N.A.",DAYS360(G7,W7)))) -> Pendiente de sentencia | AA7: N/A | AD7: FIJA CAUCION | AE7: 45708 | AF7: CAROLINA | AG7: 01 CIVIL MCPAL | AH7: ELECTRONICO
A8: 1 | B8: Así mismo se deberá cumplir la ritualidad contemplada en el artículo 375 del CGP, sumando a la fijación de la valla que cumpla con (i) las dimensiones legales; (ii) la información que debe contener y (iii) el lugar de ubicación y el tiempo que debe permanecer alii, conforme al numeral 7° del multicitado canon 375 de la ley 1564 de 2012, y la inclusión mediática alii contemplada en el registro de procesos de pertenencia. | C8: PERTENENCIA | D8: VERBAL | E8: MINIMA | F8: REMITIDA POR OTRO DESPACHO | G8: 45568 | H8: IMPORTADORA GIRATORIA SAS | I8: 1 | J8: 0 | K8: HECTOR EMILIO LOPERA QUICENO | L8: 1 | M8: 0 | N8: 45568 | O8: =IF(G8="","",(IF(N8="","Pendiente primera actuación",IF(N8="N.A.","N.A.",IF(NETWORKDAYS((G8+1),N8,'Días No Laborales'!$A$2:$U$145)<=20,"SI","NO"))))) -> SI | Q8: NO | Y8: N/A | Z8: =IF(B8="","",IF(W8="","Pendiente de sentencia",IF(W8="N.A.","N.A.",DAYS360(G8,W8)))) -> Pendiente de sentencia | AA8: N/A | AD8: REQUIERE | AE8: 45842 | AF8: CAMILA | AG8: 01 CIVIL MCPAL | AH8: ELECTRONICO | AM8: P. OFICIOS - EMPLAZAMIENTO
A9: 2 | C9: PRESCRIPCIÓN EXTINTIVA OBLIGACION HIPOTECARIA | D9: DECLARATIVO VERBAL SUMARIO OTROS PROCESO | E9: MINIMA | F9: REMITIDA POR OTRO DESPACHO | G9: 45566 | H9: HERNANDO DE JESUS GONZALEZ CORTES | I9: 1 | J9: 0 | K9: MARIA JUDITH GONZALES DE GUTIERREZ | L9: 0 | M9: 1 | N9: 45568 | O9: =IF(G9="","",(IF(N9="","Pendiente primera actuación",IF(N9="N.A.","N.A.",IF(NETWORKDAYS((G9+1),N9,'Días No Laborales'!$A$2:$U$145)<=20,"SI","NO"))))) -> SI | Q9: NO | W9: 45670 | Y9: N/A | Z9: =IF(B9="","",IF(W9="","Pendiente de sentencia",IF(W9="N.A.","N.A.",DAYS360(G9,W9)))) -> 102 | AA9: N/A | AB9: DESISTIMIENTO TACITO | AC9: 2025-1 | AD9: TERMINA PROCESO POR DESISTIMIENTO | AE9: 45670 | AF9: LACIDES | AG9: 01 CIVIL MCPAL | AH9: ELECTRONICO | AI9: 45715 | AM9: Vence Req. 05/12/2024
A10: 3 | B10: Se le informa a la parte actora que una vez se encuentre instalada la valla o el aviso, deberá aportar fotografías del inmueble en las que se observe el contenido de ellos y la certificación expedida por la empresa responsable de elaborar la valla con las dimensiones requeridas. La valla o el aviso deberán permanecer instalados hasta la audiencia de instrucción y juzgamiento. | C10: NULIDAD ABSOLUTA CONTRATO | D10: DECLARATIVO VERBAL OTROS PROCESO | E10: MENOR | F10: REMITIDA POR OTRO DESPACHO | G10: 45568 | H10: NATHALIA CORDOBA CASTAÑO | I10: 0 | J10: 1 | K10: JULIANA URIBE MEJIA | L10: 0 | M10: 1 | N10: 45568 | O10: =IF(G10="","",(IF(N10="","Pendiente primera actuación",IF(N10="N.A.","N.A.",IF(NETWORKDAYS((G10+1),N10,'Días No Laborales'!$A$2:$U$145)<=20,"SI","NO"))))) -> SI | Q10: NO | Y10: N/A | Z10: =IF(B10="","",IF(W10="","Pendiente de sentencia",IF(W10="N.A.","N.A.",DAYS360(G10,W10)))) -> Pendiente de sentencia | AA10: N/A | AD10: INCORPORA Y PONE EN CONOCIMIENTO | AE10: 45797 | AF10: CAMILA | AG10: 01 CIVIL MCPAL | AH10: ELECTRONICO
A11: 4 | B11: 001-2023-00453 | C11: RESPONSABILIDAD CIVIL EXTRACONTRACTUAL | D11: DECLARATIVO VERBAL SUMARIO OTROS PROCESO | E11: MINIMA | F11: REMITIDA POR OTRO DESPACHO | G11: 45566 | H11: CESAR AUGUSTO CALLE OQUENDO | I11: 1 | J11: 0 | K11: SANTIAGO DUQUE ALVAREZ Y OTROS | L11: 0 | M11: 1 | N11: 45566 | O11: =IF(G11="","",(IF(N11="","Pendiente primera actuación",IF(N11="N.A.","N.A.",IF(NETWORKDAYS((G11+1),N11,'Días No Laborales'!$A$2:$U$145)<=20,"SI","NO"))))) -> SI | Q11: NO | W11: 45721 | Y11: N/A | Z11: =IF(B11="","",IF(W11="","Pendiente de sentencia",IF(W11="N.A.","N.A.",DAYS360(G11,W11)))) -> 154 | AA11: N/A | AB11: DESISTIMIENTO TACITO | AC11: 2025-1 | AD11: DECRETA DESISTIMIENTO TACITO ART. 317 | AE11: 45721 | AF11: LACIDES | AG11: 01 CIVIL MCPAL | AH11: ELECTRONICO | AI11: 45729 | AM11: Vence Req. 05/12/2024
A12: 5 | B12: 001-2023-00619 | C12: RESTITUCION BIEN INMUEBLE | D12: VERBAL SUMARIO | E12: MINIMA | F12: REMITIDA POR OTRO DESPACHO | G12: 45565 | H12: GERENCIAR Y SERVIR SAS | I12: 1 | J12: 0 | K12: HEYMAR LOPEZ VILLAMIZAR | L12: 1 | M12: 0 | N12: 45565 | O12: =IF(G12="","",(IF(N12="","Pendiente primera actuación",IF(N12="N.A.","N.A.",IF(NETWORKDAYS((G12+1),N12,'Días No Laborales'!$A$2:$U$145)<=20,"SI","NO"))))) -> SI | Q12: NO | W12: 45580 | Y12: N/A | Z12: =IF(B12="","",IF(W12="","Pendiente de sentencia",IF(W12="N.A.","N.A.",DAYS360(G12,W12)))) -> 15 | AA12: N/A | AB12: SENTENCIA ANTICIPADA | AC12: 2024-4 | AD12: SENTENCIA ANTICIPADA | AE12: 45580 | AF12: CAROLINA | AG12: 01 CIVIL MCPAL | AH12: ELECTRONICO
A13: 6 | B13: 001-2023-00960 | C13: PAGO POR CONSIGNACIÓN | D13: DECLARATIVO VERBAL SUMARIO OTROS PROCESO | E13: MINIMA | F13: REMITIDA POR OTRO DESPACHO | G13: 45567 | H13: MARIA DEL CARMEN RESTREPO VELEZ | I13: 0 | J13: 1 | K13: BLANCA LIGIA PEREZ MONA | L13: 0 | M13: 1 | N13: 45567 | O13: =IF(G13="","",(IF(N13="","Pendiente primera actuación",IF(N13="N.A.","N.A.",IF(NETWORKDAYS((G13+1),N13,'Días No Laborales'!$A$2:$U$145)<=20,"SI","NO"))))) -> SI | Q13: NO | Y13: N/A | Z13: =IF(B13="","",IF(W13="","Pendiente de sentencia",IF(W13="N.A.","N.A.",DAYS360(G13,W13)))) -> Pendiente de sentencia | AA13: N/A | AD13: ORDENA REAJUSTAR CONSIGNACION | AE13: 45840 | AF13: LACIDES | AG13: 01 CIVIL MCPAL | AH13: ELECTRONICO
A14: 7 | B14: 001-2023-01227 | C14: RESTITUCION BIEN INMUEBLE | D14: VERBAL SUMARIO | E14: MINIMA | F14: REMITIDA POR OTRO DESPACHO | G14: 45567 | H14: HERNAN ALBERTO GARCES BEDOYA | I14: 1 | J14: 0 | K14: LINA MARCELA MEJIA LONDOÑO | L14: 0 | M14: 1 | N14: 45567 | O14: =IF(G14="","",(IF(N14="","Pendiente primera actuación",IF(N14="N.A.","N.A.",IF(NETWORKDAYS((G14+1),N14,'Días No Laborales'!$A$2:$U$145)<=20,"SI","NO"))))) -> SI | Q14: NO | W14: 45811 | Y14: N/A | Z14: =IF(B14="","",IF(W14="","Pendiente de sentencia",IF(W14="N.A.","N.A.",DAYS360(G14,W14)))) -> 241 | AA14: N/A | AB14: DESISTIMIENTO TACITO | AC14: 2025-2 | AD14: DESISTIMIENTO TACITO PROCESO | AE14: 45811 | AF14: CAROLINA | AG14: 01 CIVIL MCPAL | AH14: ELECTRONICO
A15: 8 | B15: 001-2023-01613 | C15: EJECUTIVO | D15: POR SUMAS DE DINERO | E15: MINIMA | F15: REMITIDA POR OTRO DESPACHO | G15: 45568 | H15: DAISY JANETH PASCUAL MONSALVE | I15: 0 | J15: 1 | K15: JUAN ESTEBAN VANEGAS ECHAVARRIA | L15: 1 | M15: 0 | N15: 45568 | O15: =IF(G15="","",(IF(N15="","Pendiente primera actuación",IF(N15="N.A.","N.A.",IF(NETWORKDAYS((G15+1),N15,'Días No Laborales'!$A$2:$U$145)<=20,"SI","NO"))))) -> SI | Q15: NO | Y15: N/A | Z15: =IF(B15="","",IF(W15="","Pendiente de sentencia",IF(W15="N.A.","N.A.",DAYS360(G15,W15)))) -> Pendiente de sentencia | AA15: N/A | AD15: REQUIERE 30 DÌAS | AE15: 45713 | AF15: CAROLINA | AG15: 01 CIVIL MCPAL | AH15: ELECTRONICO
A16: 9 | B16: 001-2023-01614 | C16: EJECUTIVO | D16: POR SUMAS DE DINERO | E16: MINIMA | F16: REMITIDA POR OTRO DESPACHO | G16: 45568 | H16: URBANIZACIÓN RESERVA DE LA MARIA | I16: 1 | J16: 0 | K16: BANCOLOMBIA Y OTROS | L16: 1 | M16: 0 | N16: 45568 | O16: =IF(G16="","",(IF(N16="","Pendiente primera actuación",IF(N16="N.A.","N.A.",IF(NETWORKDAYS((G16+1),N16,'Días No Laborales'!$A$2:$U$145)<=20,"SI","NO"))))) -> SI | Q16: NO | W16: 45686 | Y16: N/A | Z16: =IF(B16="","",IF(W16="","Pendiente de sentencia",IF(W16="N.A.","N.A.",DAYS360(G16,W16)))) -> 116 | AA16: N/A | AB16: TERMINA POR PAGO TOTAL | AC16: 2025-1 | AD16: INCORPORA Y RESUELVE | AE16: 45859 | AF16: CAMILA | AG16: 01 CIVIL MCPAL | AH16: ELECTRONICO | AI16: 46004
A17: 10 | B17: 001-2024-00018 | C17: EJECUTIVO | D17: POR SUMAS DE DINERO | E17: MENOR | F17: REMITIDA POR OTRO DESPACHO | G17: 45568 | H17: BANCO DAVIVIENDA | I17: 1 | J17: 0 | K17: WILLIAM GALLEGO HURTADO | L17: 1 | M17: 0 | N17: 45568 | O17: =IF(G17="","",(IF(N17="","Pendiente primera actuación",IF(N17="N.A.","N.A.",IF(NETWORKDAYS((G17+1),N17,'Días No Laborales'!$A$2:$U$145)<=20,"SI","NO"))))) -> SI | Q17: NO | Y17: N/A | Z17: =IF(B17="","",IF(W17="","Pendiente de sentencia",IF(W17="N.A.","N.A.",DAYS360(G17,W17)))) -> Pendiente de sentencia | AA17: N/A | AD17: REQUIERE 5 DIAS | AE17: 45841 | AF17: LACIDES | AG17: 01 CIVIL MCPAL | AH17: ELECTRONICO
A18: 11 | B18: 001-2024-00031 | C18: EJECUTIVO | D18: POR SUMAS DE DINERO | E18: MINIMA | F18: REMITIDA POR OTRO DESPACHO | G18: 45568 | H18: SEGUROS COMERCIALES BOLIVAR | I18: 1 | J18: 0 | K18: LOURDES GARCIA Y OTROS | L18: 0 | M18: 1 | N18: 45568 | O18: =IF(G18="","",(IF(N18="","Pendiente primera actuación",IF(N18="N.A.","N.A.",IF(NETWORKDAYS((G18+1),N18,'Días No Laborales'!$A$2:$U$145)<=20,"SI","NO"))))) -> SI | Q18: NO | W18: 45670 | Y18: N/A | Z18: =IF(B18="","",IF(W18="","Pendiente de sentencia",IF(W18="N.A.","N.A.",DAYS360(G18,W18)))) -> 100 | AA18: N/A | AB18: ORDENA SEGUIR ADELANTE CON LA EJECUCIÓN | AC18: 2025-1 | AD18: REQUIERE 5 DIAS | AE18: 45841 | AF18: LACIDES | AG18: 01 CIVIL MCPAL | AH18: ELECTRONICO | AJ18: X
A19: 12 | B19: 001-2024-00032 | C19: EJECUTIVO | D19: POR SUMAS DE DINERO | E19: MINIMA | F19: REMITIDA POR OTRO DESPACHO | G19: 45568 | H19: RENTA INVERSIONES INMOBILIARIA | I19: 1 | J19: 0 | K19: DOUGLAS ENRIQUE VALBUENA RINCON | L19: 1 | M19: 0 | N19: 45568 | O19: =IF(G19="","",(IF(N19="","Pendiente primera actuación",IF(N19="N.A.","N.A.",IF(NETWORKDAYS((G19+1),N19,'Días No Laborales'!$A$2:$U$145)<=20,"SI","NO"))))) -> SI | Q19: NO | Y19: N/A | Z19: =IF(B19="","",IF(W19="","Pendiente de sentencia",IF(W19="N.A.","N.A.",DAYS360(G19,W19)))) -> Pendiente de sentencia | AA19: N/A | AD19: TERMINA DESISTIMIENTO TACITO MEDIDA | AE19: 45807 | AF19: CAROLINA | AG19: 01 CIVIL MCPAL | AH19: ELECTRONICO
A20: 13 | B20: 001-2024-00035 | C20: EJECUTIVO | D20: POR SUMAS DE DINERO | E20: MENOR | F20: REMITIDA POR OTRO DESPACHO | G20: 45568 | H20: BANCO SCOTIBANK COLPATRIA S.A | I20: 1 | J20: 0 | K20: PAULA ANDREA GALEANO MARULANDA | L20: 0 | M20: 1 | N20: 45568 | O20: =IF(G20="","",(IF(N20="","Pendiente primera actuación",IF(N20="N.A.","N.A.",IF(NETWORKDAYS((G20+1),N20,'Días No Laborales'!$A$2:$U$145)<=20,"SI","NO"))))) -> SI | Q20: NO | W20: 45572 | Y20: N/A | Z20: =IF(B20="","",IF(W20="","Pendiente de sentencia",IF(W20="N.A.","N.A.",DAYS360(G20,W20)))) -> 4 | AA20: N/A | AB20: ORDENA SEGUIR ADELANTE CON LA EJECUCIÓN | AC20: 2024-4 | AD20: TERMINA X PAGO CON OSAE | AE20: 45862 | AF20: CAMILA | AG20: 01 CIVIL MCPAL | AH20: ELECTRONICO | AJ20: X
A21: 14 | B21: 001-2024-00053 | C21: EJECUTIVO | D21: POR SUMAS DE DINERO | E21: MENOR | F21: REMITIDA POR OTRO DESPACHO | G21: 45568 | H21: BANCO DE OCCIDENTE S.A | I21: 1 | J21: 0 | K21: DIANA CAROLINA LOPERA FLOREZ | L21: 0 | M21: 1 | N21: 45568 | O21: =IF(G21="","",(IF(N21="","Pendiente primera actuación",IF(N21="N.A.","N.A.",IF(NETWORKDAYS((G21+1),N21,'Días No Laborales'!$A$2:$U$145)<=20,"SI","NO"))))) -> SI | Q21: NO | W21: 45569 | Y21: N/A | Z21: =IF(B21="","",IF(W21="","Pendiente de sentencia",IF(W21="N.A.","N.A.",DAYS360(G21,W21)))) -> 1 | AA21: N/A | AB21: ORDENA SEGUIR ADELANTE CON LA EJECUCIÓN | AC21: 2024-4 | AD21: ORDENA TRASLADO | AE21: 45841 | AF21: LACIDES | AG21: 01 CIVIL MCPAL | AH21: ELECTRONICO | AJ21: X
A22: 15 | B22: 001-2024-00074 | C22: EJECUTIVO | D22: POR SUMAS DE DINERO | E22: MINIMA | F22: REMITIDA POR OTRO DESPACHO | G22: 45568 | H22: COTRAFA COOPERATIVA FINANCIERA | I22: 1 | J22: 0 | K22: DIANA MARCELA MAZO CASTRO | L22: 0 | M22: 1 | N22: 45568 | O22: =IF(G22="","",(IF(N22="","Pendiente primera actuación",IF(N22="N.A.","N.A.",IF(NETWORKDAYS((G22+1),N22,'Días No Laborales'!$A$2:$U$145)<=20,"SI","NO"))))) -> SI | Q22: NO | W22: 45572 | Y22: N/A | Z22: =IF(B22="","",IF(W22="","Pendiente de sentencia",IF(W22="N.A.","N.A.",DAYS360(G22,W22)))) -> 4 | AA22: N/A | AB22: ORDENA SEGUIR ADELANTE CON LA EJECUCIÓN | AC22: 2024-4 | AD22: APRUEBA LIQUIDACION CREDITO | AE22: 45750 | AF22: CAROLINA | AG22: 01 CIVIL MCPAL | AH22: ELECTRONICO | AJ22: X
A23: 16 | B23: 001-2024-00078 | C23: EJECUTIVO | D23: POR SUMAS DE DINERO | E23: MINIMA | F23: REMITIDA POR OTRO DESPACHO | G23: 45568 | H23: ALAMACENES EXITOS S.A | I23: 1 | J23: 0 | K23: GIOVANNY ALEXANDER HERNANDEZ | L23: 1 | M23: 0 | N23: 45568 | O23: =IF(G23="","",(IF(N23="","Pendiente primera actuación",IF(N23="N.A.","N.A.",IF(NETWORKDAYS((G23+1),N23,'Días No Laborales'!$A$2:$U$145)<=20,"SI","NO"))))) -> SI | Q23: NO | W23: 45574 | Y23: N/A | Z23: =IF(B23="","",IF(W23="","Pendiente de sentencia",IF(W23="N.A.","N.A.",DAYS360(G23,W23)))) -> 6 | AA23: N/A | AB23: ORDENA SEGUIR ADELANTE CON LA EJECUCIÓN | AC23: 2024-4 | AD23: APRUEBA LIQUIDACION CREDITO | AE23: 45714 | AF23: CAMILA | AG23: 01 CIVIL MCPAL | AH23: ELECTRONICO | AJ23: X | AM23: P. COSTAS
A24: 17 | B24: 001-2024-00083 | C24: EJECUTIVO | D24: POR SUMAS DE DINERO | E24: MINIMA | F24: REMITIDA POR OTRO DESPACHO | G24: 45568 | H24: BANCO FINANDINA S.A | I24: 1 | J24: 0 | K24: CARLOS ANDRES MORALES ECHAVARRIA | L24: 1 | M24: 0 | N24: 45568 | O24: =IF(G24="","",(IF(N24="","Pendiente primera actuación",IF(N24="N.A.","N.A.",IF(NETWORKDAYS((G24+1),N24,'Días No Laborales'!$A$2:$U$145)<=20,"SI","NO"))))) -> SI | Q24: NO | W24: 45617 | Y24: N/A | Z24: =IF(B24="","",IF(W24="","Pendiente de sentencia",IF(W24="N.A.","N.A.",DAYS360(G24,W24)))) -> 48 | AA24: N/A | AB24: ORDENA SEGUIR ADELANTE CON LA EJECUCIÓN | AC24: 2024-4 | AD24: ORDENA TRASLADO Y REQUIERE 5 DIAS | AE24: 45841 | AF24: LACIDES | AG24: 01 CIVIL MCPAL | AH24: ELECTRONICO | AJ24: X
A25: 18 | B25: 001-2024-00097 | C25: EJECUTIVO | D25: POR SUMAS DE DINERO | E25: MINIMA | F25: REMITIDA POR OTRO DESPACHO | G25: 45568 | H25: NUEVO SUR INMOBILIARIA S.A.S | I25: 1 | J25: 0 | K25: OSCAR LEONARDO RODRIGUEZ HERNANDEZ | L25: 1 | M25: 0 | N25: 45568 | O25: =IF(G25="","",(IF(N25="","Pendiente primera actuación",IF(N25="N.A.","N.A.",IF(NETWORKDAYS((G25+1),N25,'Días No Laborales'!$A$2:$U$145)<=20,"SI","NO"))))) -> SI | Q25: NO | Y25: N/A | Z25: =IF(B25="","",IF(W25="","Pendiente de sentencia",IF(W25="N.A.","N.A.",DAYS360(G25,W25)))) -> Pendiente de sentencia | AA25: N/A | AD25: REQUIERE | AE25: 45799 | AF25: CAROLINA | AG25: 01 CIVIL MCPAL | AH25: ELECTRONICO
A26: 19 | B26: 001-2024-00100 | C26: RESPONSABILIDAD CIVIL CONTRACTUAL | D26: DECLARATIVO VERBAL OTROS PROCESO | E26: MINIMA | F26: REMITIDA POR OTRO DESPACHO | G26: 45568 | H26: LISETH ALEJANDRA GUTIERREZ MARIN | I26: 0 | J26: 1 | K26: MARTHA ELENA LONDOÑO Y OTROS | L26: 0 | M26: 1 | N26: 45568 | O26: =IF(G26="","",(IF(N26="","Pendiente primera actuación",IF(N26="N.A.","N.A.",IF(NETWORKDAYS((G26+1),N26,'Días No Laborales'!$A$2:$U$145)<=20,"SI","NO"))))) -> SI | Q26: NO | Y26: N/A | Z26: =IF(B26="","",IF(W26="","Pendiente de sentencia",IF(W26="N.A.","N.A.",DAYS360(G26,W26)))) -> Pendiente de sentencia | AA26: N/A | AD26: NOTIFICACION PERSONAL ALGUNOS DEMDOS | AE26: 45744 | AF26: LINA | AG26: 01 CIVIL MCPAL | AH26: ELECTRONICO
A27: 20 | B27: 001-2024-00103 | C27: EJECUTIVO | D27: POR SUMAS DE DINERO | E27: MINIMA | F27: REMITIDA POR OTRO DESPACHO | G27: 45568 | H27: UNIDAD RESIDENCIAL AIRE DEL BOSQUE | I27: 1 | J27: 0 | K27: MARIA DORA MURIEL ECHEVERRI | L27: 1 | M27: 0 | N27: 45568 | O27: =IF(G27="","",(IF(N27="","Pendiente primera actuación",IF(N27="N.A.","N.A.",IF(NETWORKDAYS((G27+1),N27,'Días No Laborales'!$A$2:$U$145)<=20,"SI","NO"))))) -> SI | Q27: NO | Y27: N/A | Z27: =IF(B27="","",IF(W27="","Pendiente de sentencia",IF(W27="N.A.","N.A.",DAYS360(G27,W27)))) -> Pendiente de sentencia | AA27: N/A | AD27: REQUIERE ART. 317 | AE27: 45814 | AF27: LUISA | AG27: 01 CIVIL MCPAL | AH27: ELECTRONICO
A28: 21 | B28: 001-2024-00105 | C28: EJECUTIVO | D28: POR SUMAS DE DINERO | E28: MINIMA | F28: REMITIDA POR OTRO DESPACHO | G28: 45568 | H28: ALCATOP SAS | I28: 1 | J28: 0 | K28: CONSTRUCCIONES TORRE LA VEGA DEL SUR | L28: 1 | M28: 0 | N28: 45568 | O28: =IF(G28="","",(IF(N28="","Pendiente primera actuación",IF(N28="N.A.","N.A.",IF(NETWORKDAYS((G28+1),N28,'Días No Laborales'!$A$2:$U$145)<=20,"SI","NO"))))) -> SI | Q28: NO | Y28: N/A | Z28: =IF(B28="","",IF(W28="","Pendiente de sentencia",IF(W28="N.A.","N.A.",DAYS360(G28,W28)))) -> Pendiente de sentencia | AA28: N/A | AD28: DECRETA TEMRINACION MEDIDA CAUTELAR Y REQUIERE ART. 317 | AE28: 45797 | AF28: CAROLINA | AG28: 01 CIVIL MCPAL | AH28: ELECTRONICO | AM28: VENCEN LO 30 DÍAS EL 22/JULIO/2025
A29: 22 | B29: 001-2024-00107 | C29: EJECUTIVO | D29: POR SUMAS DE DINERO | E29: MENOR | F29: REMITIDA POR OTRO DESPACHO | G29: 45568 | H29: JUAN DAVID JARAMILLO CORREA | I29: 1 | J29: 0 | K29: ALVARO FERNANDO SALAZAR GUERRERO Y OTRO | L29: 1 | M29: 0 | N29: 45568 | O29: =IF(G29="","",(IF(N29="","Pendiente primera actuación",IF(N29="N.A.","N.A.",IF(NETWORKDAYS((G29+1),N29,'Días No Laborales'!$A$2:$U$145)<=20,"SI","NO"))))) -> SI | Q29: NO | W29: 45687 | Y29: N/A | Z29: =IF(B29="","",IF(W29="","Pendiente de sentencia",IF(W29="N.A.","N.A.",DAYS360(G29,W29)))) -> 117 | AA29: N/A | AB29: TERMINA POR PAGO TOTAL | AC29: 2025-1 | AD29: TERMINA POR PAGO | AE29: 45687 | AF29: CAMILA | AG29: 01 CIVIL MCPAL | AH29: ELECTRONICO | AI29: 45693
A30: 23 | B30: 001-2024-00126 | C30: EJECUTIVO | D30: POR SUMAS DE DINERO | E30: MENOR | F30: REMITIDA POR OTRO DESPACHO | G30: 45568 | H30: BANCO DE BOGOTA | I30: 1 | J30: 0 | K30: NAFER JOSE PEÑA BERTEL | L30: 1 | M30: 0 | N30: 45568 | O30: =IF(G30="","",(IF(N30="","Pendiente primera actuación",IF(N30="N.A.","N.A.",IF(NETWORKDAYS((G30+1),N30,'Días No Laborales'!$A$2:$U$145)<=20,"SI","NO"))))) -> SI | Q30: NO | W30: 45617 | Y30: N/A | Z30: =IF(B30="","",IF(W30="","Pendiente de sentencia",IF(W30="N.A.","N.A.",DAYS360(G30,W30)))) -> 48 | AA30: N/A | AB30: ORDENA SEGUIR ADELANTE CON LA EJECUCIÓN | AC30: 2024-4 | AD30: REQUIERE 10 DIAS | AE30: 45842 | AF30: LACIDES | AG30: 01 CIVIL MCPAL | AH30: ELECTRONICO | AJ30: x
A31: 24 | B31: 001-2024-00141 | C31: DIVISORIO | D31: DIVISORIO | E31: MENOR | F31: REMITIDA POR OTRO DESPACHO | G31: 45568 | H31: OLGA ISABEL OROZCO PATIÑO | I31: 0 | J31: 1 | K31: LEOPOLDO DE JESUS JIMENEZ GOMEZ Y OTRO | L31: 1 | M31: 0 | N31: 45568 | O31: =IF(G31="","",(IF(N31="","Pendiente primera actuación",IF(N31="N.A.","N.A.",IF(NETWORKDAYS((G31+1),N31,'Días No Laborales'!$A$2:$U$145)<=20,"SI","NO"))))) -> SI | Q31: NO | W31: 45621 | Y31: N/A | Z31: =IF(B31="","",IF(W31="","Pendiente de sentencia",IF(W31="N.A.","N.A.",DAYS360(G31,W31)))) -> 52 | AA31: N/A | AB31: TERMINA PROCESO POR DESISTIMIENTO | AC31: 2024-4 | AD31: TERMINA PROCESO POR DESISTIMIENTO | AE31: 45621 | AF31: LACIDES | AG31: 01 CIVIL MCPAL | AH31: ELECTRONICO | AM31: TEMRINADO POR DESISTIMIENTO
A32: 25 | B32: 001-2024-00174 | C32: EJECUTIVO | D32: POR SUMAS DE DINERO | E32: MINIMA | F32: REMITIDA POR OTRO DESPACHO | G32: 45568 | H32: COBELEN | I32: 0 | J32: 1 | K32: JUAN FELIPE CARVAJAL NOREÑA Y OTRO | L32: 1 | M32: 2 | N32: 45568 | O32: =IF(G32="","",(IF(N32="","Pendiente primera actuación",IF(N32="N.A.","N.A.",IF(NETWORKDAYS((G32+1),N32,'Días No Laborales'!$A$2:$U$145)<=20,"SI","NO"))))) -> SI | Q32: NO | W32: 45574 | Y32: N/A | Z32: =IF(B32="","",IF(W32="","Pendiente de sentencia",IF(W32="N.A.","N.A.",DAYS360(G32,W32)))) -> 6 | AA32: N/A | AB32: ORDENA SEGUIR ADELANTE CON LA EJECUCIÓN | AC32: 2024-4 | AD32: SUSPENDE PROCESO | AE32: 45680 | AF32: CAROLINA | AG32: 01 CIVIL MCPAL | AH32: ELECTRONICO
A33: 26 | B33: 001-2024-00175 | C33: EJECUTIVO | D33: POR SUMAS DE DINERO | E33: MINIMA | F33: REMITIDA POR OTRO DESPACHO | G33: 45568 | H33: AECSA S.A | I33: 1 | J33: 0 | K33: NURY DEL SOCORRO CHAVERRA BENITEZ | L33: 0 | M33: 0 | N33: 45568 | O33: =IF(G33="","",(IF(N33="","Pendiente primera actuación",IF(N33="N.A.","N.A.",IF(NETWORKDAYS((G33+1),N33,'Días No Laborales'!$A$2:$U$145)<=20,"SI","NO"))))) -> SI | Q33: NO | Z33: =IF(B33="","",IF(W33="","Pendiente de sentencia",IF(W33="N.A.","N.A.",DAYS360(G33,W33)))) -> Pendiente de sentencia | AB33: ORDENA SEGUIR ADELANTE CON LA EJECUCIÓN | AC33: 2024-4 | AD33: REQUIERE ART. 317 | AE33: 45846 | AF33: CAMILA | AG33: 01 CIVIL MCPAL | AH33: ELECTRONICO | AJ33: X
A34: 27 | B34: 001-2024-00213 | C34: EJECUTIVO | D34: POR SUMAS DE DINERO | E34: MINIMA | F34: REMITIDA POR OTRO DESPACHO | G34: 45568 | H34: BANCOLOMBIA S.A | I34: 0 | J34: 1 | K34: JHON EDISON MADRIGAL LONDOÑO | L34: 0 | M34: 1 | N34: 45568 | O34: =IF(G34="","",(IF(N34="","Pendiente primera actuación",IF(N34="N.A.","N.A.",IF(NETWORKDAYS((G34+1),N34,'Días No Laborales'!$A$2:$U$145)<=20,"SI","NO"))))) -> SI | Q34: NO | W34: 45828 | Y34: N/A | Z34: =IF(B34="","",IF(W34="","Pendiente de sentencia",IF(W34="N.A.","N.A.",DAYS360(G34,W34)))) -> 257 | AA34: N/A | AB34: ORDENA SEGUIR ADELANTE CON LA EJECUCION | AC34: 2025-2 | AD34: ORDENA TRASLADO LIQUIDACION CRDITO | AE34: 45866 | AF34: CAROLINA | AG34: 01 CIVIL MCPAL | AH34: ELECTRONICO
A35: 28 | B35: 001-2024-00240 | C35: EJECUTIVO | D35: POR SUMAS DE DINERO | E35: MENOR | F35: REMITIDA POR OTRO DESPACHO | G35: 45568 | H35: BANCO DE BOGOTA | K35: ALVARO FERNANDO TORO RENDON | L35: 1 | M35: 0 | N35: 45575 | O35: =IF(G35="","",(IF(N35="","Pendiente primera actuación",IF(N35="N.A.","N.A.",IF(NETWORKDAYS((G35+1),N35,'Días No Laborales'!$A$2:$U$145)<=20,"SI","NO"))))) -> SI | Q35: NO | W35: 45575 | Y35: N/A | Z35: =IF(B35="","",IF(W35="","Pendiente de sentencia",IF(W35="N.A.","N.A.",DAYS360(G35,W35)))) -> 7 | AA35: N/A | AB35: ORDENA SEGUIR ADELANTE CON LA EJECUCIÓN | AC35: 2024-4 | AD35: OSAE - COSTAS | AE35: 45575 | AF35: LUISA | AG35: 01 CIVIL MCPAL | AH35: ELECTRONICO
A36: 29 | B36: 001-2024-00263 | C36: EJECUTIVO | D36: POR SUMAS DE DINERO | E36: MINIMA | F36: REMITIDA POR OTRO DESPACHO | G36: 45568 | H36: GUILLERMO LEON BENITEZ GARCIA | I36: 1 | J36: 0 | K36: YESSICA YULIANA HERNANDEZ FRANCO | L36: 1 | M36: 0 | N36: 45568 | O36: =IF(G36="","",(IF(N36="","Pendiente primera actuación",IF(N36="N.A.","N.A.",IF(NETWORKDAYS((G36+1),N36,'Días No Laborales'!$A$2:$U$145)<=20,"SI","NO"))))) -> SI | Q36: NO | W36: 45734 | Y36: N/A | Z36: =IF(B36="","",IF(W36="","Pendiente de sentencia",IF(W36="N.A.","N.A.",DAYS360(G36,W36)))) -> 165 | AA36: N/A | AB36: ORDENA SEGUIR ADELANTE CON LA EJECUCIÓN | AC36: 2025-1 | AD36: REQUIERE | AE36: 45842 | AF36: LACIDES | AG36: 01 CIVIL MCPAL | AH36: ELECTRONICO
A37: 30 | B37: 001-2024-00277 | C37: EJECUTIVO | D37: POR SUMAS DE DINERO | E37: MINIMA | F37: REMITIDA POR OTRO DESPACHO | G37: 45568 | H37: SEGUROS COMERCIALES BOLIVAR | I37: 1 | J37: 1 | K37: ROGER ALEXANDER FLOREZ GIRLDO | L37: 1 | M37: 0 | N37: 45569 | O37: =IF(G37="","",(IF(N37="","Pendiente primera actuación",IF(N37="N.A.","N.A.",IF(NETWORKDAYS((G37+1),N37,'Días No Laborales'!$A$2:$U$145)<=20,"SI","NO"))))) -> SI | Q37: NO | W37: 45574 | Y37: N/A | Z37: =IF(B37="","",IF(W37="","Pendiente de sentencia",IF(W37="N.A.","N.A.",DAYS360(G37,W37)))) -> 6 | AA37: N/A | AB37: ORDENA SEGUIR ADELANTE CON LA EJECUCIÓN | AC37: 2024-4 | AD37: OSAE - COSTAS | AE37: 45581 | AF37: CAROLINA | AG37: 01 CIVIL MCPAL | AH37: ELECTRONICO
A38: 31 | B38: 001-2024-00279 | C38: EJECUTIVO | D38: POR SUMAS DE DINERO | E38: MINIMA | F38: REMITIDA POR OTRO DESPACHO | G38: 45568 | H38: DORIS ELENA ZAPATA | I38: 1 | J38: 0 | K38: JORGE ALBERTO GIRALDO RESTREPO | L38: 1 | M38: 0 | N38: 45568 | O38: =IF(G38="","",(IF(N38="","Pendiente primera actuación",IF(N38="N.A.","N.A.",IF(NETWORKDAYS((G38+1),N38,'Días No Laborales'!$A$2:$U$145)<=20,"SI","NO"))))) -> SI | Q38: NO | Y38: N/A | Z38: =IF(B38="","",IF(W38="","Pendiente de sentencia",IF(W38="N.A.","N.A.",DAYS360(G38,W38)))) -> Pendiente de sentencia | AA38: N/A | AD38: AUTORIZA NUEVA DIRECCION | AE38: 45799 | AF38: LUISA | AG38: 01 CIVIL MCPAL | AH38: ELECTRONICO
A39: 32 | B39: 001-2024-00282 | C39: EJECUTIVO | D39: POR SUMAS DE DINERO | E39: MINIMA | F39: REMITIDA POR OTRO DESPACHO | G39: 45568 | H39: ANIBAL ARISTIZABAL HOYOS | I39: 1 | J39: 0 | K39: MANUEL RAMIREZ SIERRA | L39: 1 | M39: 0 | N39: 45568 | O39: =IF(G39="","",(IF(N39="","Pendiente primera actuación",IF(N39="N.A.","N.A.",IF(NETWORKDAYS((G39+1),N39,'Días No Laborales'!$A$2:$U$145)<=20,"SI","NO"))))) -> SI | Q39: NO | Y39: N/A | Z39: =IF(B39="","",IF(W39="","Pendiente de sentencia",IF(W39="N.A.","N.A.",DAYS360(G39,W39)))) -> Pendiente de sentencia | AA39: N/A | AD39: REQ. ART. 317 | AE39: 45679 | AF39: LUISA | AG39: 01 CIVIL MCPAL | AH39: ELECTRONICO
A40: 33 | B40: 001-2024-00289 | C40: RESTITUCION BIEN INMUEBLE | D40: VERBAL SUMARIO | E40: MINIMA | F40: REMITIDA POR OTRO DESPACHO | G40: 45568 | H40: BANCOLOMBIA S.A | I40: 1 | J40: 0 | K40: JOSE FERNANDO ROMERO GUARDAMINO | L40: 0 | M40: 0 | N40: 45568 | O40: =IF(G40="","",(IF(N40="","Pendiente primera actuación",IF(N40="N.A.","N.A.",IF(NETWORKDAYS((G40+1),N40,'Días No Laborales'!$A$2:$U$145)<=20,"SI","NO"))))) -> SI | Q40: NO | W40: 45709 | Y40: N/A | Z40: =IF(B40="","",IF(W40="","Pendiente de sentencia",IF(W40="N.A.","N.A.",DAYS360(G40,W40)))) -> 138 | AA40: N/A | AB40: SENTENCIA ANTICIPADA | AC40: 2025-1 | AD40: ORDENA EXPEDIR COMISION | AE40: 45804 | AF40: CAROLINA | AG40: 01 CIVIL MCPAL | AH40: ELECTRONICO | AI40: 45662
A41: 34 | B41: 001-2024-00297 | C41: EJECUTIVO | D41: POR SUMAS DE DINERO | E41: MENOR | F41: REMITIDA POR OTRO DESPACHO | G41: 45568 | H41: BANCO DE OCCIDENTE | I41: 0 | J41: 1 | K41: MARIA ALEJANDRA PATIÑO RUIZ | L41: 0 | M41: 1 | N41: 45568 | O41: =IF(G41="","",(IF(N41="","Pendiente primera actuación",IF(N41="N.A.","N.A.",IF(NETWORKDAYS((G41+1),N41,'Días No Laborales'!$A$2:$U$145)<=20,"SI","NO"))))) -> SI | Q41: NO | Z41: =IF(B41="","",IF(W41="","Pendiente de sentencia",IF(W41="N.A.","N.A.",DAYS360(G41,W41)))) -> Pendiente de sentencia | AB41: REMITIDOS A OTROS DESPACHOS | AC41: 2024-4 | AD41: INCORPORA/RESPONDE | AE41: 45723 | AF41: LACIDES | AG41: 01 CIVIL MCPAL | AH41: ELECTRONICO | AM41: REMITIDO 09/12/2024
A42: 35 | B42: 001-2024-00312 | C42: EJECUTIVO | D42: POR SUMAS DE DINERO | E42: MINIMA | F42: REMITIDA POR OTRO DESPACHO | G42: 45568 | H42: ALBERTO NARANJO S.A | I42: 1 | J42: 0 | K42: OSWALDO DE JESUS GOMEZ RAMIREZ | L42: 1 | M42: 1 | N42: 45568 | O42: =IF(G42="","",(IF(N42="","Pendiente primera actuación",IF(N42="N.A.","N.A.",IF(NETWORKDAYS((G42+1),N42,'Días No Laborales'!$A$2:$U$145)<=20,"SI","NO"))))) -> SI | Q42: NO | W42: 45735 | Y42: N/A | Z42: =IF(B42="","",IF(W42="","Pendiente de sentencia",IF(W42="N.A.","N.A.",DAYS360(G42,W42)))) -> 166 | AA42: N/A | AB42: DESISTIMIENTO TACITO | AC42: 2025-1 | AD42: TERMINA POR DESISTIMIENTO TACITO | AE42: 45735 | AF42: CAMILA | AG42: 01 CIVIL MCPAL | AH42: ELECTRONICO | AI42: 45743 | AM42: TERMINA DESISTIMIENTO TACITO
A43: 36 | B43: 001-2024-00319 | C43: EJECUTIVO | D43: POR SUMAS DE DINERO | E43: MINIMA | F43: REMITIDA POR OTRO DESPACHO | G43: 45568 | H43: BANCO DE OCCIDENTE | I43: 1 | J43: 0 | K43: LUIS ALFREDO ALTAMAR ROJAS | L43: 1 | M43: 0 | N43: 45568 | O43: =IF(G43="","",(IF(N43="","Pendiente primera actuación",IF(N43="N.A.","N.A.",IF(NETWORKDAYS((G43+1),N43,'Días No Laborales'!$A$2:$U$145)<=20,"SI","NO"))))) -> SI | Q43: NO | W43: 45713 | Y43: N/A | Z43: =IF(B43="","",IF(W43="","Pendiente de sentencia",IF(W43="N.A.","N.A.",DAYS360(G43,W43)))) -> 142 | AA43: N/A | AB43: ORDENA SEGUIR ADELANTE CON LA EJECUCIÓN | AC43: 2025-1 | AD43: ORDENA CORRER TRASLADO | AE43: 45798 | AF43: CAROLINA | AG43: 01 CIVIL MCPAL | AH43: ELECTRONICO
...

Sheet Tutelas
C1: SEGUIMIENTO A TÉRMINOS PROCESALES - TUTELAS
C2: PROCESO MEJORAMIENTO DE LA GESTIÓN
A4: Juzgado | C4: Juzgado 004 Civil Municipal de Envigado
A6: N° | B6: N° RADICADO | C6: ACCIONANTE | D6: ACCIONADO | E6: FECHA DE INGRESO dd-mm-aaaa | F6: OTRAS ENTRADAS | G6: ASIGNADO | H6: ALERTA | I6: NO. DIAS | J6: DIA SIETE | K6: DIA DIEZ | L6: PERSPECTIVA DE GÉNERO (SI/NO) | M6: CON MEDIDA PROVISIONAL | N6: LUGAR DE ORIGEN | P6: INSTANCIA | Q6: CUADERNOS | R6: FOLIOS | S6: FECHA DE LA SENTENCIA dd-mm-aaaa | T6: ¿DICTÓ SENTENCIA DENTRO DEL TÉRMINO? (si/no) | U6: OBSERVACIONES (EN CASO DE NO CUMPLIR LOS TÉRMINOS) | V6: No. DE DÍAS | W6: Fecha de archivo o de salida sin decisión definitiva | X6: DERECHO FUNDAMENTAL INVOCADO | Y6: DERECHO FUNDAMENTAL TUTELADO | Z6: DECISIÓN | AA6: ¿SE IMPUGNÓ? | AB6: FECHA LIMITE IMPUGNACION | AC6: FECHA REMISIÓN CORTE/CIRCUITO | AD6: DECISIÓN SEGUNDA INSTANCIA | AE6: FECHA REGRESO | AF6: ARCHIVO DEFINITIVO | AG6: OBSERVACIONES
A7: 1 | B7: 2024-00001 | C7: RENATA SOTO PEREZ | D7: FLOSILDA SAS | E7: 45564 | F7: REPARTO | G7: DANIELA | H7: =IF(E7="","",IF(S7<>"","",IF(NETWORKDAYS(E7+1,TODAY(),'Días No Laborales'!$E$1:$U$146)>=7,"ALERTA",""))) | I7: 6 | J7: =WORKDAY(E7,7,'Días No Laborales'!$A$1:$U$141) -> 45573 | K7: =IF(E7="","",WORKDAY(E7,10,'Días No Laborales'!$B$1:$U$142)) -> 45576 | L7: NO | M7: NO | N7: CENTRO DE SERVICIOS ADMINISTRATIVOS | S7: 45566 | T7: =IF(S7="","",IF(E7="RECHAZA ","RECHAZA ",IF(E7="","",(IF(E7="Pendiente sentencia","Pendiente sentencia",IF(E7=" "," ",IF(NETWORKDAYS((E7+1),S7,'Días No Laborales'!$A$2:$U$160)<=10,"SI","NO"))))))) -> SI | U7: =IF(T7="","",IF(T7="NO","OBSERVACIÓN","N.A")) -> N.A | V7: =IF(S7="","",IF(E7="","",NETWORKDAYS(E7+1,S7,'Días No Laborales'!$A$1:$U$141))) -> 2 | X7: SALUD | Y7: N/A | Z7: IMPROCEDENTE | AA7: NO | AB7: 45573 | AC7: 45610
A8: 2 | B8: 2024-00007 | C8: OMAIRA MARIA CAIDEO GARCIA | D8: SECRETARIA EDUCACION/MUNICIPIO ENVIGADO | E8: 45560 | F8: REPARTO | G8: CAMILA | H8: =IF(E8="","",IF(S8<>"","",IF(NETWORKDAYS(E8+1,TODAY(),'Días No Laborales'!$E$1:$U$146)>=7,"ALERTA",""))) | I8: 6 | J8: =WORKDAY(E8,7,'Días No Laborales'!$A$1:$U$141) -> 45569 | K8: =IF(E8="","",WORKDAY(E8,10,'Días No Laborales'!$B$1:$U$142)) -> 45574 | L8: NO | M8: NO | N8: CENTRO DE SERVICIOS ADMINISTRATIVOS | S8: 45569 | T8: =IF(S8="","",IF(E8="RECHAZA ","RECHAZA ",IF(E8="","",(IF(E8="Pendiente sentencia","Pendiente sentencia",IF(E8=" "," ",IF(NETWORKDAYS((E8+1),S8,'Días No Laborales'!$A$2:$U$160)<=10,"SI","NO"))))))) -> SI | U8: =IF(T8="","",IF(T8="NO","OBSERVACIÓN","N.A")) -> N.A | V8: =IF(S8="","",IF(E8="","",NETWORKDAYS(E8+1,S8,'Días No Laborales'!$A$1:$U$141))) -> 7 | X8: PETICION | Y8: PETICION | Z8: CONCEDE | AA8: SI | AB8: 45576 | AC8: 45582 | AD8: CONFIRMA | AE8: 45587
A9: 3 | B9: 2024-00010 | C9: LINA PATRICIA PEREZ MARTINEZ | D9: EPS SURAMERICANA S.A.S | E9: 45562 | F9: REPARTO | G9: LACIDES | H9: =IF(E9="","",IF(S9<>"","",IF(NETWORKDAYS(E9+1,TODAY(),'Días No Laborales'!$E$1:$U$146)>=7,"ALERTA",""))) | J9: =WORKDAY(E9,7,'Días No Laborales'!$A$1:$U$141) -> 45573 | K9: =IF(E9="","",WORKDAY(E9,10,'Días No Laborales'!$B$1:$U$142)) -> 45576 | L9: NO | M9: NO | N9: CENTRO DE SERVICIOS ADMINISTRATIVOS | S9: 45562 | T9: =IF(S9="","",IF(E9="RECHAZA ","RECHAZA ",IF(E9="","",(IF(E9="Pendiente sentencia","Pendiente sentencia",IF(E9=" "," ",IF(NETWORKDAYS((E9+1),S9,'Días No Laborales'!$A$2:$U$160)<=10,"SI","NO"))))))) -> SI | U9: =IF(T9="","",IF(T9="NO","OBSERVACIÓN","N.A")) -> N.A | V9: =IF(S9="","",IF(E9="","",NETWORKDAYS(E9+1,S9,'Días No Laborales'!$A$1:$U$141))) -> -1 | W9: PROPONE CONFLICTO | X9: SEGURIDAD SOCIAL | Y9: N/A | Z9: PROPONE CONFLICTO | AA9: NO | AB9: N/A | AE9: 45616 | AG9: TRIBUNAL ASIGNO COMPTENCIA A ESTE DESPACHO

Sheet Tutelas - Corte
D1: CONTROL ENVIO TUTELAS A CORTE
D2: RADICADO | F2: FECHA ENVIO | G2: OK
D3: 2024-00001 | F3: 45610
D4: 2024-00013 | F4: 45610
D5: 2024-00015 | F5: 45610
D6: 2024-00019 | F6: 45610
D7: 2024-00021 | F7: 45610
D8: 2024-00023 | F8: 45610
D9: 2024-00027 | F9: 45610
D10: 2024-00033 | F10: 45610
D11: 2024-00039 | F11: 45610
D12: 2024-00042 | F12: 45610
D13: 2024-00047 | F13: 45610
D14: 2024-00048 | F14: 45610
G15: OK
D16: 2024-00056 | F16: 45631
D17: 2024-00058 | F17: 45625
D18: 2024-00060 | F18: 45625
D19: 2024-00066 | F19: 45625
D20: 2024-00069 | F20: 45625
D21: 2024-00071 | F21: 45625
D22: 2024-00078 | F22: 45625
D23: 2024-00081 | F23: 45625
D24: 2024-00084 | F24: 45625
D25: 2024-00085 | F25: 45625
D26: 2024-00095 | F26: 45625
D27: 2024-00101 | F27: 45625
D28: 2024-00103 | F28: 45625
G29: OK
D30: 2024-00107 | F30: 45645
D31: 2024-00118 | F31: 45645
D32: 2024-00124 | F32: 45645
D33: 2024-00128 | F33: 45645
D34: 2024-00131 | F34: 45645
D35: 2024-00137 | F35: 45645
D36: 2024-00149 | F36: 45645
D37: 2024-00157 | F37: 45304
D38: 2024-00162 | F38: 45645
D39: 2024-00167 | F39: 45645
D40: 2024-00169 | F40: 45645
...

Sheet Incidentes de Desacato
A1: JUZGADO CUARTO CIVIL MUNICIPAL DE ENVIGADO
A2: INCIDENTES DE DESACATO - TUTELAS
A3: RADICADO | B3: FECHA INGRESO | C3: REINGRESO NULIDAD | D3: DEMANDANTE | E3: DEMANDADO | F3: CUADERNOS | G3: DERECHO | H3: REQUERIMIENTO | I3: APERTURA | J3: P SANCION (DIA 7) | K3: ÚLTIMA ACTUACIÓN | L3: FECHA ÚLTIMA ACTUACIÓN | M3: REMITIDO A CONSULTA | N3: FECHA TERMINACION | O3: FECHA REGRESO | P3: DECISIÓN CONSULTA | Q3: UBICACIÓN EXPEDIENTE | R3: FECHA ARCHIVO DEFINITIVO | S3: CAJA | T3: INAP. SANCIÓN | U3: FECHA INAP. SANCIÓN | V3: OBSERVACIONES
A4: 2024-00023 | B4: 45587 | D4: MELISSA LAVERDE GOMEZ | E4: EMPRESAS PUBLICAS DE MEDELLIN Y OTROS | G4: PETICION | H4: 0 | I4: 0 | J4: 0 | K4: RECHAZO | L4: 45587 | N4: 45587 | Q4: ELECTRONICO | R4: 45587 | W4: LAURA
A5: 2024-00007 | B5: 45603 | D5: OMAIRA MARIA CAIDEO GARCIA | E5: SECRETARIA EDUCACION/MUNICIPIO ENVIGADO | G5: PETICION | H5: 45604 | I5: 45614 | J5: 0 | K5: SANCIONA | L5: 45624 | N5: 45624 | O5: 45628 | P5: NULIDAD | Q5: ELECTRONICO | V5: Enviado Consulta 29/11/2024 | W5: CAMILA
A6: 2024-00162 | B6: 45625 | D6: YUSMARY COROMOTO FIGUEREDO | E6: SECRETARIA SECCIONAL SALUD | G6: SALUD | H6: 0 | I6: 0 | J6: 0 | K6: RECHAZO | L6: 45628 | N6: 45628 | Q6: ELECTRONICO | R6: 45628 | W6: JHOHHAN
A7: 2024-00007 | B7: 45628 | C7: REINGRESO NULIDAD | D7: OMAIRA MARIA CAIDEO GARCIA | E7: SECRETARIA EDUCACION/MUNICIPIO ENVIGADO | G7: PETICION | H7: 45629 | I7: 0 | J7: 0 | K7: ABSTIENE APERTURAR | L7: 45638 | N7: 45638 | Q7: ELECTRONICO | R7: 45638 | V7: Reingreso | W7: CAMILA
A8: 2024-00171 | B8: 45635 | D8: JOSE MARIO USME RAMRIEZ | E8: SAVIA SALUD EPS | G8: SALUD | H8: 45636 | I8: 45639 | K8: SANCIONA | L8: 45673 | O8: 45311 | P8: CONFIRMA | Q8: ELECTRONICO | V8: ENVIADO A CONSULTA 16/01/2024 | W8: LACIDES | X8: Solo se comienza estadistica Primer t 2025
A9: 2 0 2 5 2 0 2 5 2 0 2 5
A10: 2025-00025 | B10: 45684 | C10: REINGRESO NULIDAD | D10: WILSON WBEIMAR ALVAREZ MENDEZ | E10: MARIA WENCESLAA TORRES | G10: SALUD | K10: ABSTIENE APERTURAR | L10: 45715 | N10: 45349 | W10: CAMILA
A11: 2025-00049 | B11: 45704 | C11: N/A | D11: ENRIQUE ACUÑA ALZATE | E11: SECRETARIA BELLO | G11: PETICION | H11: 45701 | I11: 45708 | J11: 1 | K11: REQUIERE PREVIO A APERTURAR | L11: 45719 | N11: 45719 | W11: CAMILA
A12: 2025-00093 | B12: 45715 | C12: N/A | D12: NEVARDO DE JESUS GALLEGO | E12: VIAJES EXITO | F12: VIAJES EXITO | G12: PETICION | H12: 45716 | I12: 45721 | J12: 45728 | K12: CIERRA INCIDENTE | L12: 45728 | N12: 45728 | W12: LACIDES
A13: 2025-00108 | B13: 45712 | C13: N/A | D13: CESAR AUGUSTO FERDINAND ACEVEDO | E13: BANCO CAJA SOCIAL | G13: PETICION | H13: 45715 | I13: 45720 | J13: 45728 | K13: CIERRA INCIDENTE | L13: 45728 | N13: 45728 | W13: LINA
A14: 2025-000112 | B14: 45722 | C14: N/A | D14: DIANA PATRICIA RODRÍGUEZ MOJICA | E14: EPS SURA - COLFONDOS | G14: SEGURIDAD SOCIAL | H14: 45723 | I14: 45730 | J14: 45750 | K14: CIERRA INCIDENTE | L14: 45750 | N14: 45750 | W14: JHOHHAN
A15: 2025-00137 | B15: 45723 | C15: N/A | D15: THE KINDER DOG S.A.S. | E15: SANITAS EPS | G15: PETICION | H15: 45726 | I15: 45730 | J15: 45737 | K15: SANCIONA | L15: 45737 | M15: 45741 | N15: 45741 | O15: 45742 | P15: CONFIRMA | Q15: ACCIONES CONSTITUCIONALES | R15: 45755 | T15: SI | U15: 45750 | V15: INAPLICA SANCION - 28/3/2025 | W15: LACIDES
A16: 2025-00175 | B16: 45727 | C16: N/A | D16: JORGE TORRES RAMIREZ | E16: ALEXANDER GOMEZ HERNANDEZ | G16: PETICION | K16: RECHAZO | L16: 45730 | N16: 45730 | W16: CAMILA
A17: 2025-00138 | B17: 45733 | C17: N/A | D17: SELSO ANTONIO CONTRERAS VIDES | E17: EPS SURAMERICANA S.A. | G17: PETICION | H17: 45733 | I17: 45733 | J17: 45736 | K17: CIERRA INCIDENTE | L17: 45736 | W17: LINA
A18: 2025-00150 | B18: 45729 | C18: N/A | D18: HOSPITAL MANUEL URIBE ÁNGEL | E18: EMPRESA SOCIAL DEL ESTADO HOSPITAL LA MARÍA | G18: PETICION | H18: 45733 | I18: 45736 | J18: 45747 | K18: SANCIONA | L18: 45747 | W18: LACIDES
A19: 2025-00097 | B19: 45734 | C19: N/A | D19: FLANKLIN RAFAEL BARIOS CELEDÓN | E19: IMPERMEABILIZADOS Y REVESTIMIENTOS CONSOLIDADOS SAS - SIC SOLUCIONES INTELIGENTES PARA LA CONSTRUCCION S.A.S. | G19: PETICION | H19: 45735 | I19: 45750 | J19: 45757 | K19: SANCIONA | L19: 45757 | N19: 45757 | O19: 45812 | P19: REVOCA | Q19: ACCIONES CONSTITUCIONALES | R19: 45771 | S19: N/A | T19: N/A | U19: N/A | V19: SANCIONA Y CONFIRMA SANCION EL SUPERIOR | W19: LINA
A20: 2025-00180 | B20: 45741 | C20: N/A | D20: NUBIA ESPERANZA MAHECHA SALAMANCA | E20: NOVEDADES PLASTICAS | G20: PETICION | H20: 45742 | I20: 45748 | J20: 45776 | K20: SANCIONA | L20: 45776 | N20: 45776 | O20: 45785 | P20: CONFIRMA | Q20: ACCIONES CONSTITUCIONALES | R20: 45785 | S20: N/A | T20: N/A | U20: N/A | V20: AUTO SANCIONA | W20: LINA
A21: 2025-00212 | B21: 45751 | C21: N/A | D21: LEIDYS ADRIANA ESPAÑA BURGOS | E21: Clínica de las Américas y Departamento de Gestión del SOAT. LA PREVISORA SA | G21: SALUD | H21: 45756 | I21: 45768 | J21: 45772 | K21: ABSTIENE DE SANCIONAR | L21: 45772 | N21: 45772 | O21: N/A | P21: N/A | Q21: ACCIONES CONSTITUCIONALES | R21: 45772 | S21: N/A | T21: N/A | U21: N/A | V21: SE ABSTIENE DE SANCIONAR | W21: LACIDES
A22: 2025-00176 | B22: 45758 | C22: N/A | D22: OCTAVIO DE JESUS CASTRILLON | E22: EPS SURAMERICANA S.A. | G22: SALUD | H22: 45772 | I22: 45784 | J22: 45791 | K22: ABSTIENE DE SANCIONAR | L22: 45791 | N22: 45791 | O22: N/A | P22: N/A | Q22: ACCIONES CONSTITUCIONALES | R22: 45797 | S22: N/A | T22: N/A | U22: N/A | V22: SE ABSTIENE DE SANCIONAR | W22: JHOHHAN
A23: 2025-00199 | B23: 45751 | C23: N/A | D23: FRANCISCO JAVIER PINZÓN SOTELO | E23: SECRETARIA DE TRÁNSITO Y MOVILIDAD DE POPAYAN | G23: PETICION | H23: 45755 | I23: 45772 | J23: 45784 | K23: ABSTIENE DE SANCIONAR | V23: SE ABSTIENE DE SANCIONAR | W23: JHOHHAN
A24: 2025-00112 | B24: 45769 | C24: N/A | D24: DIANA PATRICIA RODRÍGUEZ MOJICA | E24: COLFONDOS Y EPS SURA | G24: SALUD | H24: 45772 | I24: 45785 | J24: 45791 | K24: ABSTIENE DE SANCIONAR | L24: 45791 | M24: NO | N24: 45791 | O24: N/A | P24: N | Q24: ACCIONES CONSTITUCIONALES | R24: 45797 | S24: N/A | T24: N/A | U24: N/A | V24: SE ABSTIENE DE SANCIONAR | W24: JHOHHAN
A25: 2025-00150 | B25: 45772 | C25: N/A | D25: HOSPITAL MANUEL URIBE ÁNGEL | E25: EMPRESA SOCIAL DEL ESTADO HOSPITAL LA MARÍA | G25: PETICION | H25: 45775 | I25: tiene hasta el 30/04/2025 | K25: CIERRA INCIDENTE | L25: 45783 | N25: 45783 | O25: N/A | P25: N/A | Q25: ACCIONES CONSTITUCIONALES | R25: 45783 | S25: N/A | T25: N/A | U25: N/A | V25: CIERRA INCIDENTE | W25: LACIDES
A26: 2025-00303 | B26: 45792 | C26: N/A | D26: AURELIO ANCIZAR ARANGO MONTOYA | E26: A.F.P. PORVENIR S.A. SEGUROS DE VIDA ALFA S.A. E.P.S. SURAMERICANA S.A. | G26: SEGURIDAD SOCIAL | H26: 45793 | I26: 45799 | J26: 45806 | K26: SANCIONA | L26: 45806 | M26: 45807 | N26: 45812 | O26: 45812 | P26: REVOCA | Q26: ACCIONES CONSTITUCIONALES | V26: REVOCA SANCION | W26: LACIDES
A27: 2025-00176 | B27: 45803 | C27: N/A | D27: OCTAVIO DE JESUS CASTRILLON | E27: EPS SURAMERICANA S.A. | G27: SALUD | K27: ACEPTA DESISTIMIENTO INCIDENTE | L27: 45811 | M27: N/A | N27: 45812 | O27: N/A | P27: N/A | Q27: ACCIONES CONSTITUCIONALES | S27: N/A | T27: N/A | U27: N/A | V27: CIERRA INCIDENTE | W27: JHOHHAN
A28: 2025-00323 | B28: 45817 | C28: N/A | D28: IDEAR SOLUCIONES FINANCIERAS | E28: SERVIEXPRESS LIBA SAS | G28: PETICION | H28: 45818 | I28: 45825 | J28: 45835 | K28: SANCIONA | L28: 45835 | M28: 45839 | O28: 45842 | P28: CONFIRMA | Q28: ACCIONES CONSTITUCIONALES | S28: N/A | T28: N/A | U28: N/A | V28: CONFIRMA AUTO IMPONE SANCION - JUZGADO 001 CIVIL CIRCUITO ENVIGADO | W28: LINA
A29: 2025-00396 | B29: 45821 | C29: N/A | D29: JORGE ALBERTO ROBLEDO GIRALDO | E29: EPS SURAMERICANA S.A. | G29: SALUD | H29: 45821 | I29: 45826 | J29: 45839 | K29: SANCIONA | L29: 45839 | M29: 45839 | V29: ASIGNADA A JUZGDAO 003 CIVIL CIRCUITO | W29: LINA
A30: 2025-00321 | B30: 45821 | C30: N/A | D30: JUAN SEBASTIAN CASTAÑEDA agente oficioso de la señora JULIANA MARULANDA RESTREPO | E30: EPS SURAMERICANA S.A. | G30: SALUD | H30: 45821 | I30: 45826 | J30: 45832 | K30: SANCIONA | L30: 45832 | M30: 45834 | N30: 45839 | O30: N/A | P30: N/A | Q30: ACCIONES CONSTITUCIONALES | R30: 45842 | S30: N/A | T30: N/A | U30: N/A | V30: CONFIRMA AUTO IMPONE SANCION - JUZGADO 002 CIVIL CIRCUITO ENVIGADO | W30: CAROLINA
A31: 2025-00418 | B31: 45821 | C31: N/A | D31: ANGELA ALICIA ZAPATA SANCHEZ | E31: SUMIMEDICAL EPS | G31: SALUD | H31: 45821 | I31: 45826 | J31: 45839 | K31: ABSTIENE DE SANCIONAR | L31: 45840 | M31: N/A | N31: 45840 | O31: N/A | P31: N/A | Q31: ACCIONES CONSTITUCIONALES | R31: 45840 | S31: N/A | T31: N/A | U31: N/A | V31: SE ABSTIENE DE SANCIONAR | W31: LINA
A32: 2025-00401 | B32: 45828 | C32: N/A | D32: JOSE ALONSO LOTERO SANDOVAL actuando como agente oficioso de JIMENA AYLIN LOTERO SUAREZ | E32: EPS SURAMERICANA S.A. | G32: SALUD | H32: 45832 | I32: 45840 | J32: 45847 | K32: ABSTIENE DE SANCIONAR | L32: 45847 | M32: N/A | N32: 45847 | O32: N/A | P32: N/A | Q32: ACCIONES CONSTITUCIONALES | R32: 45853 | S32: N/A | T32: N/A | U32: N/A | V32: SE ABSTIENE DE SANCIONAR | W32: LACIDES
A33: 2025-00414 | B33: 45839 | C33: N/A | D33: ANDRES FELIPE GONZALEZ ARIAS | E33: TELEPERFORMANCE COLOMBIA EPS SURAMERICANA S.A. PROTECCIÓN S.A. | G33: SALUD | H33: 45841 | I33: PRESCINDE DE PRUEBA - 21/7/2025 | J33: 45869 | K33: SANCIONA | L33: 45869 | M33: 45873 | N33: 45877 | O33: N/A | P33: N/A | Q33: ACCIONES CONSTITUCIONALES | R33: 45883 | S33: N/A | T33: N/A | U33: N/A | V33: REVOCA SANCION - CUMPLIO EN SEDE DE CONSULTA | W33: JHOHHAN
A34: 2025-00321 | B34: 45839 | C34: N/A | D34: JUAN SEBASTIAN CASTAÑEDA agente oficioso de la señora JULIANA MARULANDA RESTREPO | E34: EPS SURAMERICANA S.A. | G34: SALUD | H34: 45842 | J34: 45847 | K34: ABSTIENE DE SANCIONAR | L34: 45847 | M34: N/A | N34: 45847 | O34: N/A | P34: N/A | Q34: ACCIONES CONSTITUCIONALES | R34: 45847 | S34: N/A | T34: N/A | U34: N/A | V34: SE ABSTIENE DE SANCIONAR | W34: CAROLINA
A35: 2025-00475 | B35: 45845 | C35: N/A | D35: NOVEDADES PLÁSTICAS S.A.S. | E35: BANCO DAVIVIENDA VINCULADO: FISCALIA 10 LOCAL DE MEDELLIN | G35: PETICION | H35: 45853 | I35: 45859 | J35: 45869 | K35: SANCIONA | L35: 45869 | M35: 45873 | N35: 45874 | O35: N/A | P35: N/A | Q35: ACCIONES CONSTITUCIONALES | R35: 45880 | S35: N/A | T35: N/A | U35: N/A | V35: REVOCA SANCION - CUMPLIO EN SEDE DE CONSULTA | W35: JHOHHAN
A36: 2025-00524 | B36: 45852 | C36: N/A | D36: Gessica Paola Ruiz Gómez | E36: IQOR Colombia S.A.S. | G36: DEBIDO PROCESO | H36: 45853 | J36: 45854 | K36: RECHAZO | L36: 45854 | M36: N/A | Q36: ACCIONES CONSTITUCIONALES | V36: RECHAZA POR NO ESTR EJECUTORIADO | W36: LACIDES
A37: 2025-00524 | B37: 45856 | C37: N/A | D37: Gessica Paola Ruiz Gómez | E37: IQOR Colombia S.A.S. | G37: DEBIDO PROCESO | H37: 45859 | I37: 45866 | J37: 45877 | K37: SANCIONA | L37: 45877 | M37: 45880 | Q37: ACCIONES CONSTITUCIONALES | V37: NO ACCEDE A INAPLICACION SE SANCION - 20/8/2025 - NO HAN CUMPLIDO COMPLET | W37: LACIDES
A38: 2025-00395 | B38: 45859 | C38: N/A | D38: IDEAR NEGOCIOS S.A.S – PRESENTE Financiero | E38: HAASS EXPRESS S.A. | G38: PETICION | H38: 45873 | J38: 45877 | K38: ABSTIENE DE SANCIONAR | L38: 45877 | M38: N/A | Q38: ACCIONES CONSTITUCIONALES | W38: CAROLINA
A39: 2025-00496 | B39: 45860 | C39: N/A | D39: IDEAR NEGOCIOS S.A.S – PRESENTE Financiero | E39: DIEGO FERNANDO RIOS SALAZAR | G39: PETICION | H39: 45862 | I39: 45870 | J39: 45877 | K39: ABSTIENE DE SANCIONAR | L39: 45877 | M39: N/A | N39: 45877 | O39: N/A | P39: N/A | Q39: ACCIONES CONSTITUCIONALES | R39: 45883 | S39: N/A | T39: N/A | U39: N/A | V39: SE ABSTIENE DE SANCIONAR | W39: CAMILA
A40: 2025-00510 | B40: 45860 | C40: N/A | D40: IDEAR NEGOCIOS S.A.S – PRESENTE Financiero | E40: DISTRIBUCIONES YEIMI S.A.S | G40: PETICION | H40: 45861 | I40: 45870 | J40: 45882 | K40: SANCIONA | L40: 45883 | Q40: ACCIONES CONSTITUCIONALES | W40: LACIDES
...

Sheet Inaplicación Inc.
A2: Radicado | B2: Fecha Ingreso | C2: Fecha Resulve Solicitud | D2: Resuelve
A3: 2024-00171 | B3: 45693 | C3: 45695 | D3: NIEGA INAPLICACION
A4: 2025-00137 | B4: 45744 | C4: 45750 | D4: INAPLICA
A5: 2025-00321 | B5: 45842 | E5: CAROLINA
A6: 2025-00323 | B6: 45848 | C6: 45848 | D6: INAPLICA | E6: LINA
A7: 2025-00414 | B7: 45870 | D7: REVOCA SANCION CIRCUITO | E7: ALEXANDER
A8: 2025-00524 | B8: 45884 | C8: 45889 | D8: NIEGA INAPLICACION | E8: LACIDES

Sheet Tutelas - Vigilancia
A3: TIPO | B3: RADICADO | C3: DEPENDENCIA | D3: FECHA LLEGADA | E3: FECHA RESPUESTA | F3: DECISIÓN
A4: 2024
A5: TUTELA | B5: 2024-00308 | C5: JUZGADO 03 CIVIL CIRCUITO | D5: 45568 | E5: 45572 | F5: NIEGA - HECHO SUPERADO
A6: VIGILANCIA | B6: 03-2024-00572 | C6: CONSEJO SECCIONAL | D6: 45573 | E6: 45575 | F6: ABSTIENE
A7: VIGILANCIA | B7: 02-2024-00429 | C7: CONSEJO SECCIONAL | D7: 45587 | E7: 45590 | F7: ABSTIENE
A8: VIGILANCIA | B8: 02-2024-00557 | C8: CONSEJO SECCIONAL | D8: 45642 | E8: 45305 | F8: ABSTIENE
A10: 2025
A11: TIPO | B11: RADICADO | C11: DEPENDENCIA | D11: FECHA LLEGADA | E11: FECHA RESPUESTA | F11: DECISIÓN | G11: IMPUGNARON/ | H11: VENCE IMPUGNACION | I11: DECISION
A12: VIGILANCIA | B12: 02-2024-00530 | C12: CONSEJO SECCIONAL | D12: 45671 | E12: 45674 | F12: ABSTIENE
A13: TUTELA | B13: 02-2024-00288 | C13: JUZGADO 02 CIVIL CIRCUITO | D13: 45672 | E13: 45673 | F13: NIEGA - INEXISTENCIA VULNERACION
A14: TUTELA | B14: 04-2024-00161 | C14: JUZGADO 01 CIVIL CTO | D14: 45673 | E14: 45677 | F14: HECHO SUPERADO
A15: TUTELA | B15: 031-2025-00090 | C15: J. 31 PENAL MPAL CONTROL GARANTIAS | D15: 45728
A16: TUTELA | B16: 002-2025-00134-00 | C16: JUZGADO 02 CIVIL CIRCUITO | D16: 45757 | E16: 45757 | F16: REQUIERE AUTO NOTIFICANDO VINCULADOS - 22/04/2025
A17: PETICION | B17: SIN RADICADO | C17: DAVID MATEO LEIVA SILVA | E17: 45758 | F17: RESUELTO Y OCULTAMIENTO REALIZADO POR JAIBER
A18: VIGILANCIA | B18: 2024-00273 | C18: EDWARD PINZON COGOLLO | D18: 45769 | E18: 45770 | F18: ORDENA ARCHIVAR VIGILANCIA
A19: VIGILANCIA | B19: 2025-00009 | C19: CONSEJO SECCIONAL | D19: 45770 | E19: 45775 | F19: ORDENA ARCHIVAR VIGILANCIA
A20: TUTELA | B20: 2025-00325 | D20: 45792 | E20: 45797 | F20: ORDENA ARCHIVAR VIGILANCIA
A21: VIGILANCIA | B21: 2024-00174 | C21: CONSEJO SECCIONAL | D21: 45797 | E21: 45798 | F21: ORDENA ARCHIVAR VIGILANCIA
A22: VIGILANCIA | B22: 2025-00009 | C22: CONSEJO SECCIONAL | D22: 45798 | E22: 45805 | F22: ORDENA ARCHIVAR VIGILANCIA
A23: TUTELA | B23: 014-2025-00281 | C23: JUZGADO 14 PENAL CON FCG MEDELLIN | D23: 45841 | E23: 45845 | F23: DECLARA IMPROCEDENTE POR INEXISTENCIA DE C VULNERADORA | G23: SI | H23: HASTA EL 31/07/2025
A24: TUTELA | B24: 002-2025-00293 | C24: JUZGADO 002 CIVIL CIRCUITO DE ENVIGADO | D24: 45853 | E24: 45862 | F24: NIEGA TUTELA - Y DEJA SIN EFECTOS LA MEDIDA PROVISIONAL CONCEDIDA | G24: SI | H24: HASTA EL 30/08/2025
A25: TUTELA | B25: 001-2025-00315-00 | C25: JUZGADO 001 CVIL DEL CIRCUITO DE ENVIGADO | D25: 45855 | E25: 45855 | F25: NIEGA - INEXISTENCIA VULNERACION | G25: N/A
A26: TUTELA | B26: 015-2025-01278-00 | C26: JUZGADO 15 CIVIL MUNICIPAL DE ENVIGADO | D26: 45870 | E26: 45873 | F26: NIEGA - INEXISTENCIA VULNERACION | G26: N/A

Sheet Acciones Populares
E1: SEGUIMIENTO A TÉRMINOS PROCESALES - ACCIONES POPULARES
E2: PROCESO MEJORAMIENTO DE LA GESTIÓN
A4: Juzgado | E4: Juzgado Primero Civil Circuito
A6: NO. | B6: N° RADICADO | C6: Demandante | D6: Demandado | E6: FECHA DE INGRESO (dd-mm-aaaa) | F6: FECHA DEL AUTO DE ADMISIÓN O NO (dd-mm-aaaa) | G6: ¿CUMPLIÓ CON EL TÉRMINO DE ADMISIÓN/INADMISIÓN? (si/no) | H6: PERSPECTIVA DE GÉNERO (SI/NO) | I6: FECHA DE LA SENTENCIA (dd-mm-aaaa) | J6: ¿DICTÓ SENTENCIA DENTRO DEL TÉRMINO? (si/no) | K6: OBSERVACIONES (EN CASO DE NO CUMPLIR LOS TÉRMINOS) | L6: No. DE DÍAS
A7: 1 | H7: NO
A8: 2 | H8: NO
A9: 3 | H9: NO
A10: 4 | H10: NO
A11: 5 | H11: NO
A12: 6 | H12: NO
A13: 7 | H13: NO
A14: 8 | H14: NO
A15: 9 | H15: NO
A16: 10 | H16: NO
A17: 11 | H17: NO
A18: 12 | H18: NO
... A61: 55 | H61: NO
A62: 56 | G62: #NAME? | H62: NO
A63: 57 | G63: #NAME? | H63: NO
A64: 58 | G64: #NAME? | H64: NO
A65: 59 | G65: #NAME? | H65: NO
A66: 60 | G66: #NAME? | H66: NO
A67: 61 | G67: #NAME? | H67: NO
A68: 62 | G68: #NAME? | H68: NO
A69: 63 | G69: #NAME? | H69: NO
A70: 64 | G70: #NAME? | H70: NO
A71: 65 | G71: #NAME? | H71: NO
A72: 66 | G72: #NAME? | H72: NO
A73: 67 | G73: #NAME? | H73: NO
... A1150: 1140 | G1150: #NAME? | H1150: NO
A1151: CONTAR SI | G1151: =COUNTIF(G7:G1150,"SI") -> 0 | H1151: =COUNTIF(H7:H1150,"SI") -> 0 | J1151: =COUNTIF(J7:J1150,"SI") -> 0
A1152: CONTAR NO | G1152: =COUNTIF(G7:G1150,"NO") -> 0 | H1152: =COUNTIF(H7:H1150,"NO") -> 1143 | J1152: =COUNTIF(J7:J1150,"NO") -> 0
A1153: TOTAL | G1153: =SUM(G1151:G1152) -> 0 | H1153: =SUM(H1151:H1152) -> 1143 | J1153: =SUM(J1151:J1152) -> 0
A1154: % DE CUMPLIMIENTO | G1154: =G1151/G1153 -> #DIV/0! | H1154: =H1151/H1153 -> 0 | J1154: =J1151/J1153 -> #DIV/0!

Sheet Habeas Corpus
E1: SEGUIMIENTO A TÉRMINOS PROCESALES - HABEAS CORPUS
E2: PROCESO MEJORAMIENTO DE LA GESTIÓN
A4: Juzgado | E4: Juzgado Primero Civil Circuito
A6: NO. | B6: N° RADICADO | C6: Accionante | D6: Accionado | E6: FECHA DE INGRESO (dd-mm-aaaa) | F6: FECHA DE RESUELVE (dd-mm-aaaa) | G6: PERSPECTIVA DE GÉNERO (SI/NO) | H6: ¿CUMPLIÓ CON EL TÉRMINO DE RESUELVE? (si/no) | I6: No. DE DÍAS
A7: 1 | G7: NO | H7: #NAME? | I7: #NAME?
A8: 2 | G8: NO | H8: =IF(NETWORKDAYS(E8,F8)<=2,"SI","NO") -> SI | I8: =NETWORKDAYS(E8,F8) -> 0
A9: 3 | G9: NO | H9: =IF(NETWORKDAYS(E9,F9)<=2,"SI","NO") -> SI | I9: =NETWORKDAYS(E9,F9) -> 0
A10: 4 | G10: NO | H10: =IF(NETWORKDAYS(E10,F10)<=2,"SI","NO") -> SI | I10: =NETWORKDAYS(E10,F10) -> 0
A11: 5 | G11: NO | H11: =IF(NETWORKDAYS(E11,F11)<=2,"SI","NO") -> SI | I11: =NETWORKDAYS(E11,F11) -> 0
A12: 6 | G12: NO | H12: =IF(NETWORKDAYS(E12,F12)<=2,"SI","NO") -> SI | I12: =NETWORKDAYS(E12,F12) -> 0
A13: 7 | G13: NO | H13: =IF(NETWORKDAYS(E13,F13)<=2,"SI","NO") -> SI | I13: =NETWORKDAYS(E13,F13) -> 0
A14: 8 | G14: NO | H14: =IF(NETWORKDAYS(E14,F14)<=2,"SI","NO") -> SI | I14: =NETWORKDAYS(E14,F14) -> 0
A15: 9 | G15: NO | H15: =IF(NETWORKDAYS(E15,F15)<=2,"SI","NO") -> SI | I15: =NETWORKDAYS(E15,F15) -> 0
A16: 10 | G16: NO | H16: =IF(NETWORKDAYS(E16,F16)<=2,"SI","NO") -> SI | I16: =NETWORKDAYS(E16,F16) -> 0
A17: 11 | G17: NO | H17: =IF(NETWORKDAYS(E17,F17)<=2,"SI","NO") -> SI | I17: =NETWORKDAYS(E17,F17) -> 0
A18: 12 | G18: NO | H18: =IF(NETWORKDAYS(E18,F18)<=2,"SI","NO") -> SI | I18: =NETWORKDAYS(E18,F18) -> 0
A19: 13 | G19: NO | H19: =IF(NETWORKDAYS(E19,F19)<=2,"SI","NO") -> SI | I19: =NETWORKDAYS(E19,F19) -> 0
... A1150: 1144 | G1150: NO | H1150: =IF(NETWORKDAYS(E1150,F1150)<=2,"SI","NO") -> SI | I1150: =NETWORKDAYS(E1150,F1150) -> 0
A1151: CONTAR SI | G1151: =COUNTIF(G7:G1150,"SI") -> 0 | H1151: =COUNTIF(H7:H1150,"SI") -> 1143
A1152: CONTAR NO | G1152: =COUNTIF(G7:G1150,"NO") -> 1144 | H1152: =COUNTIF(H7:H1150,"NO") -> 0
A1153: TOTAL | G1153: =SUM(G1151:G1152) -> 1144 | H1153: =SUM(H1151:H1152) -> 1143
A1154: % DE CUMPLIMIENTO | G1154: =G1151/G1153 -> 0 | H1154: =H1151/H1153 -> 1

Sheet Días No Laborales
A1: 2010 | B1: 2011 | C1: 2012 | D1: 2013 | E1: 2014 | F1: 2015 | G1: 2016 | H1: 2017 | I1: 2018 | J1: 2019 | K1: 2020 | L1: 2021 | M1: 2022 | N1: 2023 | O1: 2024 | P1: 2025 | Q1: 2026 | R1: 2027 | S1: 2028 | T1: 2029 | U1: 2030
A2: 40179 | B2: 40544 | C2: 40909 | D2: 41275 | E2: 41640 | F2: 42005 | G2: 42370 | H2: 42736 | I2: 43101 | J2: 43466 | K2: 43831 | L2: 44197 | M2: 44562 | N2: 44927 | O2: 45292 | P2: 45658 | Q2: 46023 | R2: 46388 | S2: 46753 | T2: 47119 | U2: 47484
A3: 40180 | B3: 40545 | C3: 40910 | D3: 41276 | E3: 41641 | F3: 42006 | G3: 42371 | H3: 42737 | I3: 43102 | J3: 43467 | K3: 43832 | L3: 44198 | M3: 44563 | N3: 44928 | O3: 45293 | P3: 45659 | Q3: 46024 | R3: 46389 | S3: 46754 | T3: 47120 | U3: 47485
A4: 40181 | B4: 40546 | C4: 40911 | D4: 41277 | E4: 41642 | F4: 42007 | G4: 42372 | H4: 42738 | I4: 43103 | J4: 43468 | K4: 43833 | L4: 44199 | M4: 44564 | N4: 44929 | O4: 45294 | P4: 45660 | Q4: 46025 | R4: 46390 | S4: 46755 | T4: 47121 | U4: 47486
A5: 40182 | B5: 40547 | C5: 40912 | D5: 41278 | E5: 41643 | F5: 42008 | G5: 42373 | H5: 42739 | I5: 43104 | J5: 43469 | K5: 43834 | L5: 44200 | M5: 44565 | N5: 44930 | O5: 45295 | P5: 45661 | Q5: 46026 | R5: 46391 | S5: 46756 | T5: 47122 | U5: 47487
A6: 40183 | B6: 40548 | C6: 40913 | D6: 41279 | E6: 41644 | F6: 42009 | G6: 42374 | H6: 42740 | I6: 43105 | J6: 43470 | K6: 43835 | L6: 44201 | M6: 44566 | N6: 44931 | O6: 45296 | P6: 45662 | Q6: 46027 | R6: 46392 | S6: 46757 | T6: 47123 | U6: 47488
A7: 40184 | B7: 40549 | C7: 40914 | D7: 41280 | E7: 41645 | F7: 42010 | G7: 42375 | H7: 42741 | I7: 43106 | J7: 43471 | K7: 43836 | L7: 44202 | M7: 44567 | N7: 44932 | O7: 45297 | P7: 45663 | Q7: 46028 | R7: 46393 | S7: 46758 | T7: 47124 | U7: 47489
A8: 40185 | B8: 40550 | C8: 40915 | D8: 41281 | E8: 41646 | F8: 42011 | G8: 42376 | H8: 42742 | I8: 43107 | J8: 43472 | K8: 43837 | L8: 44203 | M8: 44568 | N8: 44933 | O8: 45298 | P8: 45664 | Q8: 46029 | R8: 46394 | S8: 46759 | T8: 47125 | U8: 47490
A9: 40186 | B9: 40551 | C9: 40916 | D9: 41282 | E9: 41647 | F9: 42012 | G9: 42377 | H9: 42743 | I9: 43108 | J9: 43473 | K9: 43838 | L9: 44204 | M9: 44569 | N9: 44934 | O9: 45299 | P9: 45665 | Q9: 46030 | R9: 46395 | S9: 46760 | T9: 47126 | U9: 47491
A10: 40187 | B10: 40552 | C10: 40917 | D10: 41283 | E10: 41648 | F10: 42013 | G10: 42378 | H10: 42744 | I10: 43109 | J10: 43474 | K10: 43839 | L10: 44205 | M10: 44570 | N10: 44935 | O10: 45300 | P10: 45666 | Q10: 46031 | R10: 46396 | S10: 46761 | T10: 47127 | U10: 47492
A11: 40188 | B11: 40553 | C11: 40918 | D11: 41284 | E11: 41649 | F11: 42014 | G11: 42379 | H11: 42745 | I11: 43110 | J11: 43475 | K11: 43840 | L11: 44206 | M11: 44571 | N11: 44936 | O11: 45301 | P11: 45667 | Q11: 46032 | R11: 46397 | S11: 46762 | T11: 47131 | U11: 47493
A12: 40189 | B12: 40558 | C12: 40919 | D12: 41286 | E12: 41650 | F12: 42015 | G12: 42380 | H12: 42749 | I12: 43113 | J12: 43477 | K12: 43841 | L12: 44207 | M12: 44576 | N12: 44940 | O12: 45304 | P12: 45668 | Q12: 46033 | R12: 46398 | S12: 46767 | T12: 47132 | U12: 47495
... A19: 40215 | B19: 40580 | C19: 40943 | D19: 41308 | E19: 41672 | F19: 42036 | G19: 42406 | H19: 42771 | I19: 43128 | J19: 43499 | K19: 43863 | L19: 44233 | M19: 44598 | N19: 44962 | O19: 45326 | P19: 45690 | Q19: 46054 | R19: 46424 | S19: 46789 | T19: 47159 | U19: 47517
A20: 40216 | B20: 40586 | C20: 40944 | D20: 41315 | E20: 41679 | F20: 42042 | G20: 42407 | H20: =H18+7 -> 42777 | I20: 43134 | J20: 43505 | K20: 43869 | L20: 44234 | M20: 44604 | N20: 44968 | O20: 45332 | P20: 45696 | Q20: 46060 | R20: 46425 | S20: 46795 | T20: 47160 | U20: 47523
A21: 40222 | B21: 40587 | C21: 40950 | D21: 41316 | E21: 41685 | F21: 42043 | G21: 42413 | H21: 42778 | I21: 43135 | J21: 43506 | K21: 43870 | L21: 44240 | M21: 44605 | N21: 44969 | O21: 45333 | P21: 45697 | Q21: 46061 | R21: 46431 | S21: 46796 | T21: 47166 | U21: 47524
A22: 40223 | B22: 40593 | C22: 40951 | D22: 41322 | E22: 41686 | F22: 42049 | G22: 42414 | H22: 42784 | I22: 43141 | J22: 43512 | K22: 43876 | L22: 44241 | M22: 44611 | N22: 44975 | O22: 45339 | P22: 45703 | Q22: 46067 | R22: 46432 | S22: 46802 | T22: 47167 | U22: 47530
A23: 40229 | B23: 40594 | C23: 40957 | D23: 41323 | E23: 41692 | F23: 42050 | G23: 42420 | H23: 42785 | I23: 43142 | J23: 43513 | K23: 43877 | L23: 44247 | M23: 44612 | N23: 44976 | O23: 45340 | P23: 45704 | Q23: 46068 | R23: 46438 | S23: 46803 | T23: 47173 | U23: 47531
A24: 40230 | B24: 40600 | C24: 40958 | D24: 41329 | E24: 41693 | F24: 42056 | G24: 42421 | H24: 42791 | I24: 43148 | J24: 43519 | K24: 43883 | L24: 44248 | M24: 44618 | N24: 44982 | O24: 45346 | P24: 45710 | Q24: 46074 | R24: 46439 | S24: 46809 | T24: 47174 | U24: 47537
A25: 40236 | B25: 40601 | C25: 40964 | D25: 41330 | E25: 41699 | F25: 42057 | G25: 42427 | H25: 42792 | I25: 43149 | J25: 43520 | K25: 43884 | L25: 44254 | M25: 44619 | N25: 44983 | O25: 45347 | P25: 45711 | Q25: 46075 | R25: 46445 | S25: 46810 | T25: 47180 | U25: 47538
A26: 40237 | B26: 40607 | C26: 40965 | D26: 41335 | E26: 41700 | F26: 42063 | G26: 42428 | H26: 42798 | I26: 43155 | J26: 43526 | K26: 43890 | L26: 44255 | M26: 44625 | N26: 44989 | O26: 45353 | P26: 45717 | Q26: 46081 | R26: 46446 | S26: 46816 | T26: 47181 | U26: 47544
A27: 40243 | B27: 40608 | C27: 40971 | D27: 41336 | E27: 41706 | F27: 42064 | G27: 42434 | H27: 42799 | I27: 43156 | J27: 43527 | K27: 43891 | L27: 44261 | M27: 44626 | N27: 44990 | O27: 45354 | P27: 45718 | Q27: 46082 | R27: 46452 | S27: 46817 | T27: 47187 | U27: 47545
A28: 40244 | B28: 40614 | C28: 40972 | D28: 41342 | E28: 41707 | F28: 42070 | G28: 42435 | H28: 42805 | I28: 43162 | J28: 43533 | K28: 43897 | L28: 44262 | M28: 44632 | N28: 44996 | O28: 45360 | P28: 45724 | Q28: 46088 | R28: 46453 | S28: 46823 | T28: 47188 | U28: 47551
A29: 40250 | B29: 40615 | C29: 40985 | D29: 41343 | E29: 41713 | F29: 42071 | G29: 42441 | H29: 42806 | I29: 43163 | J29: 43534 | K29: 43898 | L29: 44268 | M29: 44633 | N29: 44997 | O29: 45361 | P29: 45725 | Q29: 46089 | R29: 46459 | S29: 46824 | T29: 47194 | U29: 47552
A30: 40251 | B30: 40621 | C30: 40986 | D30: 41349 | E30: 41714 | F30: 42077 | G30: 42442 | H30: 42812 | I30: 43169 | J30: 43540 | K30: 43904 | L30: 44269 | M30: 44639 | N30: 45003 | O30: 45367 | P30: 45731 | Q30: 46095 | R30: 46460 | S30: 46830 | T30: 47195 | U30: 47558
A31: 40257 | B31: 40622 | C31: 40987 | D31: 41350 | E31: 41722 | F31: 42078 | G31: 42448 | H31: 42813 | I31: 43170 | J31: 43541 | K31: 43905 | L31: 44275 | M31: 44640 | N31: 45004 | O31: 45368 | P31: 45732 | Q31: 46096 | R31: 46466 | S31: 46831 | T31: 47196 | U31: 47559
A32: 40258 | B32: 40623 | C32: 40992 | D32: 41356 | E32: 41727 | F32: 42084 | G32: 42449 | H32: 42814 | I32: 43176 | J32: 43547 | K32: 43911 | L32: 44276 | M32: 45006 | N32: 45005 | O32: 45374 | P32: 45738 | Q32: 46102 | R32: 46467 | S32: 46832 | T32: 47201 | U32: 47537
